Workbook

Sheet dados_brutos
A1: id | B1: link_pncp | C1: data_acesso | D1: uf | E1: grupo_uf | F1: municipio | G1: orgao | H1: esfera | I1: data_publicacao | J1: modalidade | K1: objeto | L1: srp | M1: areas | N1: area_principal | O1: valor_estimado_total | P1: valor_homologado_total | Q1: estimado_itens_com_resultado | R1: desconto | S1: desconto_suspeito | T1: n_itens | U1: n_com_resultado | V1: n_homologados | W1: n_desertos | X1: n_fracassados | Y1: n_anulados_cancelados | Z1: houve_deserta_ou_fracassada | AA1: exclusiva_total_meepp | AB1: exclusiva_parcial_meepp | AC1: cota_meepp | AD1: aplicou_beneficio_meepp | AE1: n_fornecedores_vencedores | AF1: vencedores_resumo | AG1: n_participantes | AH1: tipo_contrato | AI1: vigencia_meses | AJ1: cesto_aereo | AK1: munck_guindauto | AL1: aceita_munck_com_cesto | AM1: pmoc_responsavel_tecnico | AN1: crea_cft | AO1: frota_minima_trecho | AP1: atestados_trecho | AQ1: frac_material | AR1: exclusao_motivo | AS1: exclusao_evidencia | AT1: revisao_manual | AU1: incluido
A2: 00001727000193_2025_22 | B2: https://pncp.gov.br/app/editais/00001727000193/2025/22 | C2: 2026-09-27T03:01:22.148674+00:00 | D2: GO | E2: GO | F2: Goiânia | G2: GOIANIA CAMARA MUNICIPAL DE GOIANIA | H2: Municipal | I2: 2025-06-12T07:38:23 | J2: Pregão - Eletrônico | K2: Contratação de serviços de manutenção preventiva e corretiva em aparelhos de ar-condicionado, bebedouros, refrigeradores e cortinas de ar, de forma continua e ininterrupta, incluindo o fornecimento de mão de obra exclusiva e materiais, bem como a utilização de equipamentos adequados e necessários para a execução dos serviços nas dependências da Câmara Municipal de Goiânia (CMG), conforme condições e exigências estabelecidas neste Edital e seus anexos. | L2: FALSE | M2: refrigeracao | N2: refrigeracao | O2: 758998.08 | P2: 685000 | Q2: 758998.08 | R2: 0.097494423 | S2: 0 | T2: 1 | U2: 1 | V2: 1 | W2: 0 | X2: 0 | Y2: 0 | Z2: 0 | AA2: 0 | AB2: 0 | AC2: 0 | AD2: 0 | AE2: 1 | AF2: GOTHERM ENGENHARIA TERMICA LTDA:ME | AH2: pontual | AJ2: 0 | AK2: 0 | AL2: 0 | AM2: 0 | AN2: 0 | AQ2: 0 | AS2: Objeto mistura ar-condicionado, bebedouros, refrigeradores e cortinas de ar com mao de obra exclusiva; item unico do PNCP e 'Manutencao de Sistemas de Refrigeracao'. Mantido incluido como caso misto (refrigeracao comercial + climatizacao predial), sem discriminacao de valor por equipamento no PNCP. | AT2: 0 | AU2: 1
A3: 00001727000193_2025_36 | B3: https://pncp.gov.br/app/editais/00001727000193/2025/36 | C3: 2026-09-27T03:19:44.893061+00:00 | D3: GO | E3: GO | F3: Goiânia | G3: GOIANIA CAMARA MUNICIPAL DE GOIANIA | H3: Municipal | I3: 2025-10-16T07:03:21 | J3: Pregão - Eletrônico | K3: Contratação de serviços especializados de manutenção corretiva e preventiva predial, com fornecimento de mão de obra sem dedicação exclusiva, sob demanda, incluindo todo o material de consumo, equipamentos e insumos necessários à execução dos serviços em todo o prédio da Câmara Municipal de Goiânia (CMG), conforme condições, quantidades e exigências estabelecidas neste Edital e seus Anexos. | L3: FALSE | M3: manutencao_predial | N3: manutencao_predial | O3: 3282438.5 | P3: 6962052.1 | Q3: 3282438.5 | R3: 0.293 | S3: 0 | T3: 1 | U3: 1 | V3: 1 | W3: 0 | X3: 0 | Y3: 0 | Z3: 0 | AA3: 0 | AB3: 0 | AC3: 0 | AD3: 0 | AE3: 1 | AF3: MAFFENG ENGENHARIA E MANUTENCAO LTDA:Demais | AH3: pontual | AJ3: 0 | AK3: 0 | AL3: 0 | AM3: 0 | AN3: 0 | AQ3: 0 | AT3: 0 | AU3: 1
A4: 00006874000156_2026_115 | B4: https://pncp.gov.br/app/editais/00006874000156/2026/115 | C4: 2026-09-27T03:12:44.173028+00:00 | D4: GO | E4: GO | F4: Novo Brasil | G4: MUNICIPIO DE NOVO BRASIL | H4: Municipal | I4: 2026-05-26T10:52:48 | J4: Pregão - Eletrônico | K4: REGISTRO DE PREÇOS PARA FUTURA E EVENTUAL AQUISIÇÃO DE MATERIAIS ELÉTRICOS DIVERSOS, DESTINADOS À MANUTENÇÃO PREVENTIVA E CORRETIVA DA REDE ELÉTRICA PREDIAL, ILUMINAÇÃO PÚBLICA, INSTALAÇÕES ELÉTRICAS E DEMAIS DEMANDAS DAS SECRETARIAS E ÓRGÃOS VINCULADOS AO MUNICÍPIO, VISANDO GARANTIR O PLENO FUNCIONAMENTO, SEGURANÇA E CONTINUIDADE DOS SERVIÇOS PÚBLICOS MUNICIPAIS, CONFORME O EDITAL E SEUS ANEXOS | L4: TRUE | M4: iluminacao_publica | N4: iluminacao_publica | O4: 387912.9 | P4: 128579.9 | Q4: 352622.9 | R4: 0.63536146 | S4: 0 | T4: 51 | U4: 40 | V4: 51 | W4: 0 | X4: 0 | Y4: 0 | Z4: 0 | AA4: 1 | AB4: 0 | AC4: 0 | AD4: 1 | AE4: 2 | AF4: FORT COMERCIO, SERVICOS E LOCACOES LTDA:ME; DGA COMERCIO DE MATERIAIS ELETRICOS LTDA:ME | AH4: pontual | AI4: 12 | AJ4: 0 | AK4: 0 | AL4: 0 | AM4: 1 | AN4: 0 | AP4: de sua capacidade de fornecimento, as quantidades do insumo/material, deste edital. 7.5.3- Os atestados de capacidade técnica poderão ser apresentados em nome da matriz ou da filial do fornecedores. 7.5.4- O fornecedor disponibilizará caso necessário, todas as informações necessárias à comprovação d… | AQ4: 1 | AR4: fornecimento_puro | AS4: Registro de preços/contratação de fornecimento de materiais, sem mão de obra de manutenção contratada. | AT4: 1 | AU4: 0
A5: 00006874000156_2026_133 | B5: https://pncp.gov.br/app/editais/00006874000156/2026/133 | C5: 2026-09-27T03:11:40.573487+00:00 | D5: GO | E5: GO | F5: Novo Brasil | G5: MUNICIPIO DE NOVO BRASIL | H5: Municipal | I5: 2026-06-22T08:22:25 | J5: Pregão - Eletrônico | K5: [Portal de Compras Públicas] - REGISTRO DE PREÇOS PARA FUTURA E EVENTUAL AQUISIÇÃO DE MATERIAIS ELÉTRICOS DIVERSOS, DESTINADOS À MANUTENÇÃO PREVENTIVA E CORRETIVA DA REDE ELÉTRICA PREDIAL, ILUMINAÇÃO PÚBLICA, INSTALAÇÕES ELÉTRICAS E DEMAIS DEMANDAS DAS SECRETARIAS E ÓRGÃOS VINCULADOS AO MUNICÍPIO, VISANDO GARANTIR O PLENO FUNCIONAMENTO, SEGURANÇA E CONTINUIDADE DOS SERVIÇOS PÚBLICOS MUNICIPAIS, CONFORME O EDITAL E SEUS ANEXOS | L5: TRUE | M5: iluminacao_publica | N5: iluminacao_publica | O5: 387912.9 | P5: 128579.9 | Q5: 352622.9 | R5: 0.63536146 | S5: 0 | T5: 51 | U5: 40 | V5: 51 | W5: 0 | X5: 0 | Y5: 0 | Z5: 0 | AA5: 1 | AB5: 0 | AC5: 0 | AD5: 0 | AE5: 2 | AF5: FORT COMERCIO, SERVICOS E LOCACOES EIRELI:EPP; DGA COMERCIO DE MATERIAIS ELETRICOS LTDA:Demais | AH5: pontual | AI5: 12 | AJ5: 0 | AK5: 0 | AL5: 0 | AM5: 1 | AN5: 0 | AP5: de sua capacidade de fornecimento, as quantidades do insumo/material, deste edital. 7.5.3- Os atestados de capacidade técnica poderão ser apresentados em nome da matriz ou da filial do fornecedores. 7.5.4- O fornecedor disponibilizará caso necessário, todas as informações necessárias à comprovação d… | AQ5: 1 | AR5: fornecimento_puro | AS5: Registro de preços/contratação de fornecimento de materiais, sem mão de obra de manutenção contratada. | AT5: 1 | AU5: 0
A6: 00044834000107_2025_2 | B6: https://pncp.gov.br/app/editais/00044834000107/2025/2 | C6: 2026-09-27T03:07:27.393338+00:00 | D6: GO | E6: GO | F6: Vicentinópolis | G6: MUNICIPIO DE VICENTINOPOLIS | H6: Municipal | I6: 2025-01-27T16:20:29 | J6: Pregão - Presencial | K6: contratação de empresa especializada, para a prestação de serviços de manutenção corretiva e preventiva, carga de gás, montagem e desmontagem em aparelhos de ar condicionado | L6: TRUE | M6: climatizacao | N6: climatizacao | O6: 1030703.3 | P6: 353941 | Q6: 1030703.3 | R6: 0.65660244 | S6: 0 | T6: 30 | U6: 30 | V6: 30 | W6: 0 | X6: 0 | Y6: 0 | Z6: 0 | AA6: 0 | AB6: 1 | AC6: 0 | AD6: 1 | AE6: 3 | AF6: SV RESPLANDE ENGENHARIA E CONSULTORIA E SERVICOS:ME; MEGA CLIMA ENGENHARIA TERMICA LTDA:ME; ULTRALAR PREGAO E REFRIGERACAO VCT LTDA:ME | AH6: indefinido | AJ6: 0 | AK6: 0 | AL6: 0 | AM6: 0 | AN6: 0 | AQ6: 0 | AS6: heuristica automatica confirmada: servico real de climatizacao, sem sinais de exclusao. | AT6: 0 | AU6: 1
A7: 00044834000107_2025_67 | B7: https://pncp.gov.br/app/editais/00044834000107/2025/67 | C7: 2026-09-27T04:41:01.450397+00:00 | D7: GO | E7: GO | F7: Vicentinópolis | G7: MUNICIPIO DE VICENTINOPOLIS | H7: Municipal | I7: 2026-01-12T14:43:30 | J7: Pregão - Presencial | K7: ADESÃO A ATA DE REGISTRO DE PREÇO Nº 009/2025, REFERENTE AO PREGÃO PRESENCIAL Nº 008/2025, TIPO SRP, PARA CONTRATAÇÃO DE EMPRESA ESPECIALIZADA PARA PRESTAÇÃO DE SERVIÇOS DE LOCAÇÃO DE ESTRUTURAS E EQUIPAMENTOS, COMO: PALCO, SONORIZAÇÃO, ILUMINAÇÃO, BANHEIROS QUÍMICOS, TENDAS, FECHAMENTO, E DEMAIS MATERIAIS NECESSÁRIOS À REALIZAÇÃO DAS FESTIVIDADES DE FINAL DE ANO DE 2025, BEM COMO DAS FESTIVIDADES A SEREM PROMOVIDAS AO LONGO DO ANO DE 2026, NO MUNICÍPIO DE VICENTINÓPOLIS. | L7: TRUE | M7: iluminacao_publica | N7: iluminacao_publica | O7: 1415716.7 | P7: 1298100 | Q7: 1415716.7 | R7: 0.083079274 | S7: 0 | T7: 18 | U7: 18 | V7: 18 | W7: 0 | X7: 0 | Y7: 0 | Z7: 0 | AA7: 0 | AB7: 0 | AC7: 0 | AD7: 0 | AE7: 1 | AF7: NACIONAL PROJETOS, CONSTRUCOES, PRODUCOES E SERVICOS EIRELI:Demais | AH7: indefinido | AJ7: 0 | AK7: 0 | AL7: 0 | AM7: 0 | AN7: 0 | AQ7: 0 | AR7: mencao_passagem | AS7: Locação de estrutura para eventos (palco/som/iluminação/banheiros/tendas); 'iluminação' é item do pacote de eventos, não manutenção de IP de vias. | AT7: 0 | AU7: 0
A8: 00078790000128_2025_161 | B8: https://pncp.gov.br/app/editais/00078790000128/2025/161 | C8: 2026-09-27T04:08:45.129124+00:00 | D8: GO | E8: GO | F8: Doverlândia | G8: MUNICIPIO DE DOVERLANDIA | H8: Municipal | I8: 2025-08-26T16:32:13 | J8: Pregão - Eletrônico | K8: ABERTURA DE PROCEDIMENTO LICITATORIO NA MODALIDADE CABIVEL VISANDO A AQUISIÇÃO DE MATERIAIS PARA MANUTENÇÃO DE BENS IMÓVEIS, MATERIAIS ELETRICOS, FERRAMENTAS E MATERIAIS DE SEGURANÇA E PROTEÇÃO. | L8: TRUE | M8: eletrica_predial | N8: eletrica_predial | O8: 5643196.9 | P8: 616725.02 | Q8: 1650130.6 | R8: 0.62625685 | S8: 0 | T8: 298 | U8: 40 | V8: 293 | W8: 0 | X8: 5 | Y8: 0 | Z8: 1 | AA8: 0 | AB8: 0 | AC8: 0 | AD8: 0 | AE8: 4 | AF8: 2M MATERIAIS DE CONSTRUCAO LTDA:ME; J V S COMERCIO DE VARIEDADE E SERVICOS LTDA:ME; CASTELLARI ILUMINAÇÃO E DECORAÇÃO EIRELI:ME; ARENA CERCAS E CONCERTINAS LTDA:ME | AH8: pontual | AJ8: 0 | AK8: 0 | AL8: 0 | AM8: 0 | AN8: 0 | AQ8: 1 | AR8: fornecimento_puro | AS8: Confirmada exclusao automatica (fornecimento_puro): 298 item(ns), todos classificados como material (sem servico). | AT8: 1 | AU8: 0
A9: 00079806000117_2026_18 | B9: https://pncp.gov.br/app/editais/00079806000117/2026/18 | C9: 2026-09-27T04:35:02.423482+00:00 | D9: GO | E9: GO | F9: Cachoeira Dourada | G9: MUNICIPIO DE CACHOEIRA DOURADA | H9: Municipal | I9: 2026-04-08T13:41:31 | J9: Pregão - Presencial | K9: A PRESENTE LICITAÇÃO TEM COMO OBJETO A CONTRATAÇÃO GLOBAL DE EMPRESA DO RAMO PERTINENTE, COM A FINALIDADE DE EXECUÇÃO DE SERVIÇOS DE RODEIO, PALCO, SONORIZAÇÃO, ILUMINAÇÃO, ENTRE OUTROS PARA TODA ESTRUTURA NECESSÁRIA PARA REALIZAÇÃO DO RODEIO DO DIA 14 A 17 MAIO, CONFORME ESPECIFICADOS NO ANEXO I- TERMO DE REFERÊNCIA, PARTE INTEGRANTE DO PRESENTE EDITAL | L9: TRUE | M9: iluminacao_publica | N9: iluminacao_publica | O9: 880291.62 | P9: 800000 | Q9: 880291.62 | R9: 0.091210256 | S9: 0 | T9: 36 | U9: 36 | V9: 36 | W9: 0 | X9: 0 | Y9: 0 | Z9: 0 | AA9: 0 | AB9: 0 | AC9: 0 | AD9: 0 | AE9: 1 | AF9: LM PRODUTORA E EVENTOS LTDA:ME | AH9: indefinido | AJ9: 0 | AK9: 0 | AL9: 0 | AM9: 0 | AN9: 0 | AQ9: 1 | AR9: mencao_passagem | AS9: Execução de serviços de rodeio/palco/sonorização/iluminação; evento, não manutenção de IP. | AT9: 1 | AU9: 0
A10: 00097857000171_2025_119 | B10: https://pncp.gov.br/app/editais/00097857000171/2025/119 | C10: 2026-09-27T04:12:35.228402+00:00 | D10: GO | E10: GO | F10: Santo Antônio do Descoberto | G10: MUNICIPIO DE SANTO ANTONIO DO DESCOBERTO | H10: Municipal | I10: 2025-08-05T07:11:50 | J10: Pregão - Eletrônico | K10: Contratação de empresa para aquisição de material elétrico para serviços de manutenção e instalações na iluminação pública. | L10: TRUE | M10: iluminacao_publica | N10: iluminacao_publica | O10: 2907765.6 | P10: 472407.6 | Q10: 988373.95 | R10: 0.52203556 | S10: 0 | T10: 104 | U10: 40 | V10: 104 | W10: 0 | X10: 0 | Y10: 0 | Z10: 0 | AA10: 0 | AB10: 1 | AC10: 0 | AD10: 0 | AE10: 5 | AF10: BMP IMPORTACAO EXPORTACAO DISTRIBUICAO E CONSTRUTORA LTDA:ME; BRASIL ILUMINACAO E CONSTRUCAO LTDA:ME; JOSE ADEILDO ALVES SIQUEIRA 46113240100:ME; 55.733.921 KELVEN GABRYEL NOGUEIRA DA SILVA:ME; CENTROLED DISTRIBUICAO DE MATERIAIS ELETRICOS E ILUMINACAO LTDA:ME | AH10: pontual | AJ10: 0 | AK10: 0 | AL10: 0 | AM10: 0 | AN10: 0 | AQ10: 1 | AR10: fornecimento_puro | AS10: Registro de preços/contratação de fornecimento de materiais, sem mão de obra de manutenção contratada. | AT10: 1 | AU10: 0
A11: 00145789000179_2025_395 | B11: https://pncp.gov.br/app/editais/00145789000179/2025/395 | C11: 2026-09-27T02:53:30.527260+00:00 | D11: GO | E11: GO | F11: Campinaçu | G11: MUNICIPIO DE CAMPINACU | H11: Municipal | I11: 2025-08-27T16:50:44 | J11: Pregão - Presencial | K11: PRESTAÇÃO DE SERVIÇOS DE MANUTENÇÃO (CORRETIVA E PREVENTIVA), INSTALAÇÃO E HIGIENIZAÇÃO DE CONDICIONADORES DE AR, PARA ATENDER OS FUNDOS E SECRETARIAS DO MUNICÍPIO DE CAMPINAÇU/GO | L11: TRUE | M11: climatizacao | N11: climatizacao | O11: 129149.02 | P11: 128316 | Q11: 129149.02 | R11: 0.0064500514 | S11: 0 | T11: 2 | U11: 2 | V11: 2 | W11: 0 | X11: 0 | Y11: 0 | Z11: 0 | AA11: 0 | AB11: 0 | AC11: 0 | AD11: 0 | AE11: 1 | AF11: HALLIS RIBEIRO DE SA 63324407168:ME | AH11: indefinido | AJ11: 0 | AK11: 0 | AL11: 0 | AM11: 0 | AN11: 0 | AQ11: 1 | AS11: objeto e servico de manutencao/instalacao/higienizacao continuo; itens foram cadastrados como Material pelo orgao por erro (heuristica fornecimento_puro e falso positivo). | AT11: 1 | AU11: 1
A12: 00163055000112_2025_135 | B12: https://pncp.gov.br/app/editais/00163055000112/2025/135 | C12: 2026-09-27T02:54:54.190164+00:00 | D12: GO | E12: GO | F12: Mundo Novo | G12: MUNICIPIO DE MUNDO NOVO | H12: Municipal | I12: 2025-08-21T16:38:36 | J12: Pregão - Presencial | K12: CONTRATAÇÃO DE PRESTAÇÃO DE SERVIÇOS DE INSTALAÇÃO, LIMPEZA, MANUTENÇÃO CORRETIVA E PREVENTIVA EM APARELHOS DE AR CONDICIONADO, E MANUTENÇÃO DE ELETRODOMÉSTICOS, DE FORMA PARCELADA PELO PERÍODO DE 12 (DOZE) MESES PARA MANUTENÇÃO DAS DIVERSAS SECRETARIAS DO PODER EXECUTIVO DO MUNICÍPIO DE MUNDO NOVO. | L12: TRUE | M12: climatizacao | N12: climatizacao | O12: 1325308.5 | P12: 585838 | Q12: 1325308.5 | R12: 0.55796103 | S12: 0 | T12: 10 | U12: 10 | V12: 10 | W12: 0 | X12: 0 | Y12: 0 | Z12: 0 | AA12: 0 | AB12: 0 | AC12: 0 | AD12: 0 | AE12: 2 | AF12: KE AR CLIMATIZAÇÃO LTDA:ME; JADIAEL FARIA OLIVEIRA:ME | AH12: indefinido | AJ12: 0 | AK12: 0 | AL12: 0 | AM12: 0 | AN12: 0 | AQ12: 1 | AS12: servico parcelado de 12 meses de instalacao/limpeza/manutencao de AC; itens mal cadastrados como Material pelo orgao. | AT12: 1 | AU12: 1
A13: 00236968000111_2025_55 | B13: https://pncp.gov.br/app/editais/00236968000111/2025/55 | C13: 2026-09-27T02:36:37.862953+00:00 | D13: GO | E13: GO | F13: Nova Crixás | G13: MUNICIPIO DE NOVA CRIXAS | H13: Municipal | I13: 2026-05-07T10:29:14 | J13: Pregão - Presencial | K13: CONTRATAÇÃO DE EMPRESA PARA O REGISTRO DE PREÇOS EVENTUAL CONTRATAÇÃO NA PRESTAÇÃO DE SERVIÇOS DE INSTALAÇÃO/REMOÇÃO/MANUTENÇÃO/HIGIENE/ LIMPEZA DE AR CONDICIONADO E FORNECIMENTO DE PEÇAS PARA ATENDIMENTO DA SECRETARIA DE EDUCAÇÃO, ESCOLAS E CRECHES CONFORME CONDIÇÕES E ESPECIFICAÇÕES ESTABELECIDAS NESTE EDITAL, TERMO DE REFERÊNCIA (ANEXO I) E DEMAIS ANEXOS. | L13: TRUE | M13: climatizacao | N13: climatizacao | O13: 939816.65 | P13: 774048.5 | Q13: 939816.65 | R13: 0.1763835 | S13: 0 | T13: 35 | U13: 35 | V13: 35 | W13: 0 | X13: 0 | Y13: 0 | Z13: 0 | AA13: 0 | AB13: 0 | AC13: 0 | AD13: 0 | AE13: 1 | AF13: KE AR CLIMATIZACAO LTDA:ME | AH13: pontual | AI13: 12 | AJ13: 0 | AK13: 0 | AL13: 0 | AM13: 0 | AN13: 0 | AP13: º 12.440/2011). 8.1.3. QUALIFICAÇÃO TECNICA (art. 67, da Lei nº 14.133/2021): a) No mínimo um Atestado de capacidade técnica, emitido por pessoa jurídica de direito público ou privado em nome da empresa, que comprove a aptidão de desempenho da licitante em fornecer objeto compatível ou semelhante ao… | AQ13: 1 | AS13: servico de instalacao/remocao/manutencao/higiene com fornecimento de pecas por demanda = servico, apesar de itens cadastrados como Material. | AT13: 1 | AU13: 1
A14: 00237222000122_2025_18 | B14: https://pncp.gov.br/app/editais/00237222000122/2025/18 | C14: 2026-09-27T02:43:55.101525+00:00 | D14: GO | E14: GO | F14: Goiânia | G14: CONSELHO REGIONAL DE ENFERMAGEM DE GOIAS | H14: Federal | I14: 2025-11-05T07:03:56 | J14: Pregão - Eletrônico | K14: Contratação de empresa especializada para prestação de serviços contínuos de manutenção preventiva e corretiva de ar condicionado com reposição de peças originais, sem ônus adicional para a Contratante, em aparelhos de ar condicionado que compõem o sistema de climatização tipo Fluxo Refrigerante Variável (VRF), para a nova sede do Conselho Regional de Enfermagem de Goiás. | L14: FALSE | M14: climatizacao | N14: climatizacao | O14: 375931.64 | P14: 124940 | Q14: 375931.64 | R14: 0.66765234 | S14: 0 | T14: 5 | U14: 5 | V14: 5 | W14: 0 | X14: 0 | Y14: 0 | Z14: 0 | AA14: 0 | AB14: 0 | AC14: 0 | AD14: 0 | AE14: 1 | AF14: INOVAR REFRIGERACAO LTDA:ME | AH14: indefinido | AJ14: 0 | AK14: 0 | AL14: 0 | AM14: 0 | AN14: 0 | AQ14: 0 | AS14: e manutencao preventiva/corretiva de um sistema VRF ja existente (nao fornecimento+instalacao de VRF novo); a heuristica reagiu a palavra 'VRF' na descricao do sistema atendido, nao a uma compra de equipamento. | AT14: 0 | AU14: 1
A15: 00348003000110_2026_252 | B15: https://pncp.gov.br/app/editais/00348003000110/2026/252 | C15: 2026-09-27T05:37:01.817340+00:00 | D15: TO | E15: vizinhos | F15: Palmas | G15: EMPRESA BRASILEIRA DE PESQUISA AGROPECUARIA | H15: Federal | I15: 2026-05-22T07:37:51 | J15: Pregão - Eletrônico | K15: Formação de Registro de Preços para eventual contratação de empresa especializada para prestação de serviços comuns descontinuados de manutenção predial corretiva e preventiva, com fornecimento de mão de obra e materiais, nas seguintes Unidades Descentralizadas: Embrapa Amapá, Embrapa Pesca e Aquicultura, Embrapa Agrossilvipastoril, Embrapa Acre, Embrapa Amazônia Oriental e Embrapa Rondônia, conforme especificações e demais elementos técnicos constantes deste Termo de Referênci | L15: TRUE | M15: manutencao_predial | N15: manutencao_predial | O15: 4852906.5 | P15: 2809501.9 | Q15: 3523189 | R15: 0.2025685 | S15: 0 | T15: 15 | U15: 8 | V15: 8 | W15: 0 | X15: 7 | Y15: 0 | Z15: 1 | AA15: 0 | AB15: 0 | AC15: 0 | AD15: 0 | AE15: 5 | AF15: DM CONSTRUCOES E REFORMAS LTDA:ME; DZ CONSTRUCOES LTDA:ME; PRESCOM - COMERCIO E SERVICOS DE CONSTRUCAO CIVIL LTDA:ME; INFINITY SERVICOS TECNICOS LTDA:ME; CTL CONSTRUCOES LTDA:ME | AH15: continuado | AJ15: 0 | AK15: 0 | AL15: 0 | AM15: 0 | AN15: 0 | AQ15: 0 | AT15: 0 | AU15: 1
A16: 00348003000110_2026_583 | B16: https://pncp.gov.br/app/editais/00348003000110/2026/583 | C16: 2026-09-27T05:04:49.649156+00:00 | D16: MT | E16: vizinhos | F16: Sinop | G16: EMPRESA BRASILEIRA DE PESQUISA AGROPECUARIA | H16: Federal | I16: 2026-07-22T16:52:41 | J16: Pregão - Eletrônico | K16: Registro de Preços para aquisição de materiais elétricos e hidráulicos para suprir as demandas de manutenção corretiva e preventiva das instalações físicas da Embrapa Agrossilvipastoril | L16: TRUE | M16: eletrica_predial | N16: eletrica_predial | O16: 221718.91 | P16: 12235.21 | Q16: 29354.46 | R16: 0.58319077 | S16: 0 | T16: 120 | U16: 40 | V16: 112 | W16: 0 | X16: 7 | Y16: 1 | Z16: 1 | AA16: 0 | AB16: 0 | AC16: 0 | AD16: 0 | AE16: 9 | AF16: BZX ROLAMENTOS LTDA:ME; TOTAL CONECTA SOLUCOES LTDA:ME; CBX COMERCIAL IMPORTADORA LTDA:ME; MAX QUALITY COMERCIO LTDA:ME; ONIX COMERCIO E DISTRIBUIDORA DE MATERIAIS PARA CONSTRUCAO LTDA:ME; RRW LICITA LTDA:ME; VOLT MATERIAIS ELETRICOS LTDA:ME; MAIS ENERGIA COMPONENTES ELETRICOS LTDA:ME; KP MATERIAIS ELETRICO E CONSTRUCAO LTDA:ME | AH16: pontual | AJ16: 0 | AK16: 0 | AL16: 0 | AM16: 0 | AN16: 0 | AQ16: 1 | AR16: fornecimento_puro | AS16: Confirmada exclusao automatica (fornecimento_puro): 120 item(ns), todos classificados como material (sem servico). | AT16: 1 | AU16: 0
A17: 00348003000110_2026_585 | B17: https://pncp.gov.br/app/editais/00348003000110/2026/585 | C17: 2026-09-27T04:52:34.544337+00:00 | D17: DF | E17: vizinhos | F17: Brasília | G17: EMPRESA BRASILEIRA DE PESQUISA AGROPECUARIA | H17: Federal | I17: 2026-07-23T09:42:02 | J17: Pregão - Eletrônico | K17: Contratação de serviços de manutenção preventiva e corretiva em equipamentos de refrigeração, instalação de equipamentos para sistemas de climatização e refrigeração, com fornecimento de materiais, peças de reposição a serem executados na Embrapa Recursos Genéticos e Biotecnologia, contemplando a elaboração e a implantação do Plano de Manutenção, Operação e Controle - PMOC. | L17: FALSE | M17: refrigeracao | N17: refrigeracao | O17: 823950 | P17: 338700 | Q17: 823950 | R17: 0.58893137 | S17: 0 | T17: 2 | U17: 2 | V17: 2 | W17: 0 | X17: 0 | Y17: 0 | Z17: 0 | AA17: 0 | AB17: 0 | AC17: 0 | AD17: 0 | AE17: 1 | AF17: AIE ENG TECNOLOGIA E MANUTENCAO LTDA:ME | AH17: pontual | AJ17: 0 | AK17: 0 | AL17: 0 | AM17: 0 | AN17: 0 | AQ17: 0 | AS17: Objeto: 'manutencao...em equipamentos de refrigeracao, instalacao de equipamentos para sistemas de climatizacao e refrigeracao' -- refrigeracao citada em primeiro lugar; 100% dos itens (por valor) carregam a palavra refrigeracao. | AT17: 0 | AU17: 1
A18: 00348003000110_2026_638 | B18: https://pncp.gov.br/app/editais/00348003000110/2026/638 | C18: 2026-09-27T02:30:25.729977+00:00 | D18: GO | E18: GO | F18: Santo Antônio de Goiás | G18: EMPRESA BRASILEIRA DE PESQUISA AGROPECUARIA | H18: Federal | I18: 2026-08-03T13:54:23 | J18: Pregão - Eletrônico | K18: Eventual contratação para aquisição de materiais de construção, hidráulicos, elétricos, eletrônicos, ferragens, ferramentas, ar condicionado e madeiras para manutenção de bens móveis e imóveis da Embrapa Arroz e Feijão | L18: TRUE | M18: climatizacao | N18: climatizacao | O18: 67378.3 | P18: 63900.8 | Q18: 67378.3 | R18: 0.051611572 | S18: 0 | T18: 219 | U18: 8 | V18: 8 | W18: 0 | X18: 2 | Y18: 0 | Z18: 1 | AA18: 1 | AB18: 0 | AC18: 0 | AD18: 0 | AE18: 3 | AF18: DM MADEIRAS E MATERIAIS PARA CONSTRUCAO LTDA:ME; M.R. ANDRADE IMPORTACAO E EXPORTACAO LTDA:ME; EMBALIZE EMBALAGENS LTDA:ME | AH18: pontual | AI18: 12 | AJ18: 0 | AK18: 0 | AL18: 0 | AM18: 0 | AN18: 0 | AP18: do o somatório de quantitativos havidos em mais de um atestado. 8.23. É permitida a apresentação de atestados de capacidade técnica emitidos em nome de outra empresa da qual a licitante seja subsidiária integral e/ou de subsidiária integral pertencente a licitante, desde que pertencente à mesma ativ… | AQ18: 1 | AR18: fornecimento_puro | AS18: heuristica automatica confirmada (fornecimento_puro): 219 item(ns), todos classificados como material (sem servico). | AT18: 1 | AU18: 0
A19: 00348003000110_2026_702 | B19: https://pncp.gov.br/app/editais/00348003000110/2026/702 | C19: 2026-09-27T04:54:52.884616+00:00 | D19: DF | E19: vizinhos | F19: Brasília | G19: EMPRESA BRASILEIRA DE PESQUISA AGROPECUARIA | H19: Federal | I19: 2026-08-12T13:36:32 | J19: Pregão - Eletrônico | K19: Aquisição de materiais diversos (Manutenção de bens móveis e imóveis, elétricos, insumos agropecuários, proteção, embalagens e químicos e etc) para atender a Embrapa Cerrados. | L19: FALSE | M19: eletrica_predial | N19: eletrica_predial | O19: 174657.89 | P19: 126872.15 | Q19: 174657.89 | R19: 0.27359623 | S19: 0 | T19: 79 | U19: 35 | V19: 35 | W19: 6 | X19: 38 | Y19: 0 | Z19: 1 | AA19: 1 | AB19: 0 | AC19: 0 | AD19: 0 | AE19: 10 | AF19: COMERCIAL JSM PRODUTOS AGROPECUARIOS LTDA:ME; BZX ROLAMENTOS LTDA:ME; NATIVA DISTRIBUICAO DE SUPRIMENTOS LTDA:ME; L7 SUPRIMENTOS LTDA:ME; ECO LUC LUBRIFICANTES LTDA:ME; 65.516.785 JOELISON ERICLES BARBOSA BELTRAO:ME; DIGITALHOUSE LTDA:ME; NOVA ERA IMPORTADORA LTDA:ME; DF MAQUINAS E FERRAMENTAS LTDA:ME; TY BORTHOLIN COMERCIAL LTDA:ME | AH19: pontual | AJ19: 0 | AK19: 0 | AL19: 0 | AM19: 0 | AN19: 0 | AQ19: 1 | AR19: fornecimento_puro | AS19: Confirmada exclusao automatica (fornecimento_puro): 79 item(ns), todos classificados como material (sem servico). | AT19: 1 | AU19: 0
A20: 00348003002245_2025_278 | B20: https://pncp.gov.br/app/editais/00348003002245/2025/278 | C20: 2026-09-27T04:50:10.276710+00:00 | D20: GO | E20: GO | F20: Santo Antônio de Goiás | G20: EMPRESA BRASILEIRA DE PESQUISA AGROPECUARIA | H20: Não se aplica | I20: 2025-11-13T08:52:22 | J20: Pregão - Eletrônico | K20: Formação de Registro de Preços para eventual Aquisições de um conjunto roll-on roll-off (mecanismo de içamento + plataforma) e de um Guincho agrícola giratório. | L20: TRUE | M20: munck | N20: munck | O20: 95985 | P20: 95700 | Q20: 95985 | R20: 0.0029692139 | S20: 0 | T20: 2 | U20: 1 | V20: 1 | W20: 0 | X20: 1 | Y20: 0 | Z20: 1 | AA20: 0 | AB20: 0 | AC20: 0 | AD20: 0 | AE20: 1 | AF20: AGROPRATA COMERCIO DE EQUIPAMENTOS LTDA.:ME | AH20: pontual | AI20: 12 | AJ20: 0 | AK20: 0 | AL20: 0 | AM20: 1 | AN20: 0 | AP20: ão de fases (habilitação antes da apresentação das propostas e lances)? Requisitos Específicos: - Atestado de Capacidade Técnica Demais (Veja Termo de Referência)* Lic. Exclusiva ME/EPP? Reserv. Cota ME/EPP? Exige Amostra/Dem.? Dec. nº 7.174/2010? Possibilidade de preços diferentes Possibilidade de… | AQ20: 1 | AR20: fornecimento_puro | AS20: Aquisição de guincho agrícola e kit roll-on/roll-off (equipamento novo); não é locação de serviço de munck. | AT20: 0 | AU20: 0
A21: 00394429000100_2025_966 | B21: https://pncp.gov.br/app/editais/00394429000100/2025/966 | C21: 2026-09-27T04:58:41.929005+00:00 | D21: DF | E21: vizinhos | F21: Brasília | G21: COMANDO DA AERONAUTICA | H21: Federal | I21: 2025-05-27T07:17:34 | J21: Pregão - Eletrônico | K21: Contratação de empresa especializada no serviço de içamento de cargas com a utilização de guindaste para prestar o apoio necessário à manutenção Eletromecânica Nível Parque Octaanual dos radares TA10SST/RSM970S instalados no Centro Integrado de Defesa Aérea e Controle de Tráfego Aéreo-CINDACTA I e no Destacamento de controle do Espaço Aéreo de Confins - MG (DTCEA-CF), e desmontagem das torres de telecomunicações do Destacamentos de Controle do Espaço Aéreo do Gama - DF. | L21: TRUE | M21: munck | N21: munck | O21: 124135.9 | P21: 113534.8 | Q21: 124135.9 | R21: 0.085399147 | S21: 0 | T21: 3 | U21: 3 | V21: 3 | W21: 0 | X21: 0 | Y21: 0 | Z21: 0 | AA21: 1 | AB21: 0 | AC21: 0 | AD21: 0 | AE21: 1 | AF21: C&M COMERCIO E SERVICOS LTDA:ME | AH21: indefinido | AJ21: 0 | AK21: 0 | AL21: 0 | AM21: 0 | AN21: 0 | AQ21: 0 | AS21: Içamento de cargas/equipamento com guindaste para apoio a manutenção de radares/torres -- serviço de içamento de equipamento, explicitamente no escopo. | AT21: 0 | AU21: 1
A22: 00394429000100_2026_1192 | B22: https://pncp.gov.br/app/editais/00394429000100/2026/1192 | C22: 2026-09-27T04:56:47.032033+00:00 | D22: DF | E22: vizinhos | F22: Brasília | G22: COMANDO DA AERONAUTICA | H22: Federal | I22: 2026-06-01T07:03:27 | J22: Pregão - Eletrônico | K22: Contratação de serviços de sonorização, iluminação e projeção para a Seção de Cerimonial do GABAER e Unidades Apoiadas. | L22: TRUE | M22: iluminacao_publica | N22: iluminacao_publica | O22: 996686 | P22: 356555 | Q22: 996686 | R22: 0.64225945 | S22: 0 | T22: 15 | U22: 15 | V22: 15 | W22: 0 | X22: 0 | Y22: 0 | Z22: 0 | AA22: 0 | AB22: 0 | AC22: 0 | AD22: 0 | AE22: 1 | AF22: C.L.A DOS SANTOS ESTUDIO:ME | AH22: indefinido | AJ22: 0 | AK22: 0 | AL22: 0 | AM22: 0 | AN22: 0 | AQ22: 0 | AR22: mencao_passagem | AS22: Contratação de serviços de sonorização, iluminação e projeção para cerimonial; evento, não manutenção de IP. | AT22: 0 | AU22: 0
A23: 00394429000100_2026_2144 | B23: https://pncp.gov.br/app/editais/00394429000100/2026/2144 | C23: 2026-09-27T04:54:14.891110+00:00 | D23: DF | E23: vizinhos | F23: Brasília | G23: COMANDO DA AERONAUTICA | H23: Federal | I23: 2026-08-31T04:00:07 | J23: Pregão - Eletrônico | K23: Aquisição de materiais de Elétrica e Pintura para manutenção predial. | L23: FALSE | M23: eletrica_predial | N23: eletrica_predial | O23: 180881.85 | P23: 123721.17 | Q23: 180881.85 | R23: 0.31601115 | S23: 0 | T23: 2 | U23: 2 | V23: 2 | W23: 0 | X23: 0 | Y23: 0 | Z23: 0 | AA23: 0 | AB23: 1 | AC23: 0 | AD23: 0 | AE23: 2 | AF23: K SERVICOS ADMINISTRATIVOS LTDA:ME; CASTRO ARANTES QUIMICA INDUSTRIAL LTDA:ME | AH23: pontual | AJ23: 0 | AK23: 0 | AL23: 0 | AM23: 0 | AN23: 0 | AQ23: 1 | AR23: fornecimento_puro | AS23: Confirmada exclusao automatica (fornecimento_puro): 2 item(ns), todos classificados como material (sem servico). | AT23: 1 | AU23: 0
A24: 00394452000103_2024_23284 | B24: https://pncp.gov.br/app/editais/00394452000103/2024/23284 | C24: 2026-09-27T03:02:42.659350+00:00 | D24: GO | E24: GO | F24: Goiânia | G24: COMANDO DO EXERCITO | H24: Federal | I24: 2025-05-07T07:56:45 | J24: Pregão - Eletrônico | K24: Contratação de serviços continuados de manutenção preventiva e corretiva em aparelhos condicionadores de ar, com fornecimento de peças originais novas, bem como o serviço de instalação e desinstalação dos equipamentos | L24: TRUE | M24: climatizacao | N24: climatizacao | O24: 544018.84 | P24: 237944.1 | Q24: 544018.84 | R24: 0.5626179 | S24: 0 | T24: 38 | U24: 38 | V24: 38 | W24: 0 | X24: 0 | Y24: 0 | Z24: 0 | AA24: 0 | AB24: 1 | AC24: 0 | AD24: 0 | AE24: 5 | AF24: LION SERVICOS E COMERCIO LTDA:ME; FEPV COMERCIO E SERVICOS ESPECIALIZADOS LTDA:ME; IGM2 METROLOGIA E MANUTENCAO LTDA:ME; Z-9 ENGENHARIA LTDA:ME; SV RESPLANDE ENGENHARIA E CONSULTORIA E SERVICOS LTDA:ME | AH24: continuado | AJ24: 0 | AK24: 0 | AL24: 0 | AM24: 0 | AN24: 0 | AQ24: 0 | AS24: heuristica automatica confirmada: servico real de climatizacao, sem sinais de exclusao. | AT24: 0 | AU24: 1
A25: 00394452000103_2025_14331 | B25: https://pncp.gov.br/app/editais/00394452000103/2025/14331 | C25: 2026-09-27T04:15:31.826207+00:00 | D25: GO | E25: GO | F25: Goiânia | G25: COMANDO DO EXERCITO | H25: Federal | I25: 2025-07-02T07:37:02 | J25: Pregão - Eletrônico | K25: Aquisição de materiais elétricos, de alvenaria e de manutenção em aparelhos condicionadores de ar, para serem utilizados na manutenção e conservação das instalações do Comando de Operações Especiais | L25: TRUE | M25: eletrica_predial | N25: eletrica_predial | O25: 610738.93 | P25: 59172.301 | Q25: 124665.25 | R25: 0.52535048 | S25: 0 | T25: 155 | U25: 40 | V25: 147 | W25: 0 | X25: 8 | Y25: 0 | Z25: 1 | AA25: 1 | AB25: 0 | AC25: 0 | AD25: 0 | AE25: 14 | AF25: COMERCIAL FPS LTDA:ME; RENNOVA COMERCIAL LTDA:ME; I.R. COMERCIO E MATERIAIS ELETRICOS LTDA:ME; BAOBA COMERCIAL E CONSULTORIA LTDA:ME; CENTROLED DISTRIBUICAO DE MATERIAIS ELETRICOS E ILUMINACAO LTDA:ME; COMERCIAL SPONCHIADO LTDA:ME; J. J. VITALLI:ME; CONSTRULUZ COMERCIO E IMPORTACAO DE MATERIAIS DE CONSTRUCAO E ILUMINACAO LTDA:ME; MORK TELECOM PRODUTOS E SERVICOS PARA TELECOMUNICACOES LTDA:ME; RRW LICITA LTDA:ME; TRIUNFAL MAQUINAS E FERRAMENTAS LTDA:ME; RBB LICITACOES E SERVICOS LTDA:ME; DESBRAVA ASSESSORIA E CONSULTORIA EM LICITACOES LTDA:ME; SZATA COMERCIO VAREJISTA LTDA:ME | AH25: pontual | AJ25: 0 | AK25: 0 | AL25: 0 | AM25: 0 | AN25: 0 | AQ25: 1 | AR25: fornecimento_puro | AS25: Confirmada exclusao automatica (fornecimento_puro): 155 item(ns), todos classificados como material (sem servico). | AT25: 1 | AU25: 0
A26: 00394452000103_2025_16511 | B26: https://pncp.gov.br/app/editais/00394452000103/2025/16511 | C26: 2026-09-27T04:08:01.521428+00:00 | D26: GO | E26: GO | F26: Jataí | G26: COMANDO DO EXERCITO | H26: Federal | I26: 2025-08-27T07:08:27 | J26: Pregão - Eletrônico | K26: Registro de Preços pelo prazo de 12 (doze) meses, para eventual contratação de serviços de manutenção de rede elétrica, para atender as necessidades do 41º Batalhão de Infantaria Mecanizado. | L26: TRUE | M26: eletrica_predial | N26: eletrica_predial | O26: 34606.85 | P26: 32186 | Q26: 34606.85 | R26: 0.069952914 | S26: 0 | T26: 5 | U26: 5 | V26: 5 | W26: 0 | X26: 0 | Y26: 0 | Z26: 0 | AA26: 0 | AB26: 0 | AC26: 0 | AD26: 0 | AE26: 1 | AF26: GAIARDO MONTAGENS ELETRICAS LTDA:Demais | AH26: pontual | AI26: 12 | AJ26: 0 | AK26: 0 | AL26: 0 | AM26: 0 | AN26: 0 | AQ26: 0 | AS26: Registro de precos para manutencao de rede eletrica (linhas de transmissao ate 69kV) do 41o BIM, itens de servico reais, valor pequeno (R$34,6 mil/12 meses) -- exemplo tipico de manutencao continua predial. | AT26: 0 | AU26: 1
A27: 00394452000103_2025_18092 | B27: https://pncp.gov.br/app/editais/00394452000103/2025/18092 | C27: 2026-09-27T04:50:58.430596+00:00 | D27: GO | E27: GO | F27: Goiânia | G27: COMANDO DO EXERCITO | H27: Federal | I27: 2025-09-04T07:17:57 | J27: Pregão - Eletrônico | K27: Aquisição de materiais e medicamentos de consumo odontológico para atender a demanda da Seção de Odontologia do Posto Médico da Guarnição de Goiânia – PMGu/Gna | L27: TRUE | M27: munck | N27: munck | O27: 454429.22 | P27: 57911.95 | Q27: 80911.38 | R27: 0.28425458 | S27: 0 | T27: 190 | U27: 40 | V27: 173 | W27: 0 | X27: 17 | Y27: 0 | Z27: 1 | AA27: 1 | AB27: 0 | AC27: 0 | AD27: 0 | AE27: 8 | AF27: BERITH COMERCIO DE PRODUTOS ODONTOLOGICOS LTDA:ME; MEGA DENTAL IMPORTACAO, EXPORTACAO E COMERCIO DE PRODUTOS ODONTOLOGICOS LTDA:ME; J.PINHEIRO-MATERIAIS MEDICOS E ODONTOLOGICOS LTDA:ME; DENTAL IPO LTDA:ME; DENTAL BH BRASIL COMERCIO DE PRODUTOS ODONTO-MEDICO-HOSPITALAR LTDA:ME; DENTAL BONSUCESSO PRODUTOS ODONTOLOGICOS LTDA:ME; AMP HOSPITALAR LTDA:ME; ORTHO DENTAL JF LTDA:ME | AH27: pontual | AJ27: 0 | AK27: 0 | AL27: 0 | AM27: 0 | AN27: 0 | AQ27: 1 | AR27: fora_escopo | AS27: Aquisição de materiais odontológicos; falso positivo de indexação, sem relação com munck. | AT27: 0 | AU27: 0
A28: 00394452000103_2025_23037 | B28: https://pncp.gov.br/app/editais/00394452000103/2025/23037 | C28: 2026-09-27T05:28:44.655922+00:00 | D28: MS | E28: vizinhos | F28: Corumbá | G28: COMANDO DO EXERCITO | H28: Federal | I28: 2025-11-18T07:01:46 | J28: Pregão - Eletrônico | K28: Aquisição de Material de Manutenção e Reparação Predial de bens imóveis, hidráulica e alvenaria. | L28: TRUE | M28: manutencao_predial | N28: manutencao_predial | O28: 2682099.4 | P28: 326089.72 | Q28: 334876 | R28: 0.152732 | S28: 0 | T28: 210 | U28: 40 | V28: 152 | W28: 0 | X28: 58 | Y28: 0 | Z28: 1 | AA28: 0 | AB28: 1 | AC28: 0 | AD28: 0 | AE28: 13 | AF28: GALVAO MATERIAIS DE CONSTRUCAO LTDA:ME; N S C COMERCIO E SERVICOS LTDA:ME; EREMASTER DISTRIBUIDORA DE FERRAGENS E FERRAMENTAS LTDA:ME; CLASSE A MATERIAIS PARA CONSTRUCAO LTDA -:ME; A A COSTA CONSTRUCOES LTDA:ME; J. J. VITALLI:ME; VIDOR & HEINECKE REPRESENTACOES COMERCIAIS LTDA:ME; R.A.C. CUNHA MATERIAIS P/ CONSTRUCAO LTDA:ME; GGV COMERCIAL LTDA:ME; AGRA COMERCIO DE FERRAMENTAS LTDA:ME; FERGAVI COMERCIAL LTDA:ME; BEST HYDRO COMERCIAL LTDA:ME; SOUL DISTRIBUIDORA DE PRODUTOS E EQUIPAMENTOS INDUSTRIAIS LTDA:ME | AH28: pontual | AJ28: 0 | AK28: 0 | AL28: 0 | AM28: 0 | AN28: 0 | AQ28: 1 | AR28: fornecimento_puro | AS28: 210 item(ns), todos classificados como material (sem servico). | AT28: 1 | AU28: 0
A29: 00394452000103_2025_23859 | B29: https://pncp.gov.br/app/editais/00394452000103/2025/23859 | C29: 2026-09-27T04:56:50.111833+00:00 | D29: DF | E29: vizinhos | F29: Brasília | G29: COMANDO DO EXERCITO | H29: Federal | I29: 2025-12-01T07:10:53 | J29: Pregão - Eletrônico | K29: Contratação p/ a prest de serv de manut predial, no Ed-Sede da FHE: a) serv contin de manut predial prev, corret e preditiva, com ded excl de mão de obra, forn de aparelhos, equip e ferram necessárias, e sem o forn de peça ou mat de reposição, nas inst elétricas, eletrônicas, hidrossanitárias e de combate a incêndio; b) serv eventuais, por demanda, de manut corret em motobombas, com forn de todo e qualquer insumo necessário; e c) serv eventuais, por dem, de iluminação natalina. | L29: FALSE | M29: iluminacao_publica | N29: iluminacao_publica | O29: 0 | S29: 0 | T29: 1 | U29: 0 | V29: 0 | W29: 0 | X29: 0 | Y29: 1 | Z29: 0 | AA29: 0 | AB29: 0 | AC29: 0 | AD29: 0 | AE29: 0 | AH29: indefinido | AJ29: 0 | AK29: 0 | AL29: 0 | AM29: 0 | AN29: 0 | AQ29: 0 | AR29: mencao_passagem | AS29: Contrato de manutenção predial geral (Comando do Exército) com item eventual de 'iluminação natalina'; iluminação é item incidental de manutenção predial ampla, item cancelado sem valor. | AT29: 0 | AU29: 0
A30: 00394452000103_2025_24023 | B30: https://pncp.gov.br/app/editais/00394452000103/2025/24023 | C30: 2026-09-27T05:25:54.271948+00:00 | D30: MS | E30: vizinhos | F30: Campo Grande | G30: COMANDO DO EXERCITO | H30: Federal | I30: 2025-12-03T07:14:31 | J30: Pregão - Eletrônico | K30: Aquisição de material de permanente permanente (ferramentas, informática, refrigeração, instrumentos musicais e empilhadeira) a fim de atender as demandas do 9° Batalhão de Suprimento | L30: TRUE | M30: refrigeracao | N30: refrigeracao | O30: 1070048.5 | P30: 273911.72 | Q30: 368235.54 | R30: 0.25615078 | S30: 0 | T30: 61 | U30: 40 | V30: 58 | W30: 0 | X30: 3 | Y30: 0 | Z30: 1 | AA30: 0 | AB30: 1 | AC30: 0 | AD30: 0 | AE30: 17 | AF30: FERGAVI COMERCIAL LTDA:ME; PERFECT COMERCIO DE MATERIAIS PARA CONSTRUCAO CIVIL E PRESTADORA DE SERVICOS LTD:ME; SOUL DISTRIBUIDORA DE PRODUTOS E EQUIPAMENTOS INDUSTRIAIS LTDA:ME; MLIVE COMERCIO E PROPAGANDA LTDA:ME; FERRAMENTAS E PNEUMATICOS 1001 LTDA:ME; DIOGO EMANUEL KUHN & CIA. LTDA:ME; HEIBER COMERCIO ELETRONICO LTDA:ME; BRAXPARK MAQUINAS E EQUIPAMENTOS LTDA:ME; GGV COMERCIAL LTDA:ME; AIQ FERRAMENTAS E INSTRUMENTOS LTDA:ME; PROPAGA MULTIVENDAS E SERVICOS INTEGRADOS LTDA:ME; SANITOP COMERCIAL LTDA:ME; SJS EQUIPAMENTOS LTDA:ME; PACIFIC ELETRONIC LTDA:ME; ISALTEC COMERCIO DE INSTRUMENTOS DE MEDICAO LTDA:ME; CLAUDINEI TONIETTI:ME; AUDIOVISAO ELETRO E CENTRAL DE PRODUTOS LTDA:ME | AH30: pontual | AJ30: 0 | AK30: 0 | AL30: 0 | AM30: 0 | AN30: 0 | AQ30: 1 | AR30: fornecimento_puro | AS30: 61 itens de material permanente diverso (ferramentas, informatica, refrigeracao, instrumentos musicais, empilhadeira) -- aquisicao pura e generica de bens, nao servico. | AT30: 0 | AU30: 0
A31: 00394452000103_2026_12981 | B31: https://pncp.gov.br/app/editais/00394452000103/2026/12981 | C31: 2026-09-27T04:53:39.836199+00:00 | D31: DF | E31: vizinhos | F31: Brasília | G31: COMANDO DO EXERCITO | H31: Federal | I31: 2026-07-09T04:00:25 | J31: Pregão - Eletrônico | K31: Contratação de empresa especializada do ramo de engenharia, para a prestação de serviços de manutenção predial, de forma contínua, e eventual por demanda, no Edifício-Sede e nos Pontos de Atendimentos (PA) no Distrito Federal, da Fundação Habitacional do Exército - FHE. | L31: FALSE | M31: manutencao_predial | N31: manutencao_predial | O31: 1047962.5 | P31: 924758.24 | Q31: 1047962.5 | R31: 0.11756554 | S31: 0 | T31: 1 | U31: 1 | V31: 1 | W31: 0 | X31: 0 | Y31: 0 | Z31: 0 | AA31: 0 | AB31: 0 | AC31: 0 | AD31: 0 | AE31: 1 | AF31: ENGEPROM ENGENHARIA LTDA:Demais | AH31: pontual | AJ31: 0 | AK31: 0 | AL31: 0 | AM31: 0 | AN31: 0 | AQ31: 0 | AT31: 0 | AU31: 1
A32: 00394452000103_2026_13259 | B32: https://pncp.gov.br/app/editais/00394452000103/2026/13259 | C32: 2026-09-27T04:53:35.847865+00:00 | D32: DF | E32: vizinhos | F32: Brasília | G32: COMANDO DO EXERCITO | H32: Federal | I32: 2026-07-13T14:26:02 | J32: Pregão - Eletrônico | K32: Aquisição de materiais de construção civil, de elétrico predial, de insumos para plataforma cremalheira, de combate a incêndio, para manutenção de equipamentos de refrigeração e de equipamentos/ferramentas para manutenção de viaturas, a fim de atender as demandas da Prefeitura Militar de Brasília. | L32: TRUE | M32: refrigeracao | N32: refrigeracao | O32: 4365592.8 | P32: 1032549.6 | Q32: 1345406 | R32: 0.2325368 | S32: 0 | T32: 87 | U32: 40 | V32: 81 | W32: 0 | X32: 6 | Y32: 0 | Z32: 1 | AA32: 0 | AB32: 1 | AC32: 0 | AD32: 0 | AE32: 11 | AF32: DRW COMERCIO LTDA:ME; MAX-FER TOOLS COMERCIAL LTDA:ME; F DE OLIVEIRA COMERCIO & SERVICOS LTDA:ME; E ANTONINI COMERCIO E SERVICOS LTDA:ME; DOMINUS PRO COMERCIO DE PRODUTOS E SERVICOS LTDA:ME; GARDA COMERCIAL LTDA:ME; REFINAR EMPRESARIAL ASSESSORIA EM CONTROLES ADMINISTRATIVOS LTDA:ME; DUARTE MATERIAIS PARA CONSTRUCAO LTDA:ME; IFM SERVICOS LTDA:ME; DIPAR FERRAGENS LTDA:ME; MELO E SILVA MATERIAIS PARA CONSTRUCAO LTDA:ME | AH32: pontual | AJ32: 0 | AK32: 0 | AL32: 0 | AM32: 0 | AN32: 0 | AQ32: 1 | AR32: fornecimento_puro | AS32: 87 itens, todos materiais de construcao civil/eletrica (abracadeira, grampo para cabo, chumbador, parafuso, broca) -- aquisicao pura de insumos, sem servico associado. | AT32: 1 | AU32: 0
A33: 00394452000103_2026_14034 | B33: https://pncp.gov.br/app/editais/00394452000103/2026/14034 | C33: 2026-09-27T05:55:00.635066+00:00 | D33: MG | E33: vizinhos | F33: Belo Horizonte | G33: COMANDO DO EXERCITO | H33: Federal | I33: 2026-07-21T04:00:14 | J33: Pregão - Eletrônico | K33: Aquisição de materiais, insumos, alimentos e medicamentos para o efetivo animal do CPOR/CM-BH e Órgãos Participantes. | L33: TRUE | M33: munck | N33: munck | O33: 2812372.8 | P33: 311872.79 | Q33: 417758.3 | R33: 0.25346118 | S33: 0 | T33: 201 | U33: 40 | V33: 104 | W33: 0 | X33: 94 | Y33: 3 | Z33: 1 | AA33: 0 | AB33: 1 | AC33: 0 | AD33: 0 | AE33: 14 | AF33: REAG-LAB COMERCIO DE PRODUTOS MEDICOS E HOSPITALARES LTDA:ME; 47.544.773 LAURO MARQUES DE LIMA:ME; DROGA MAIS VET DISTRIBUIDORA DE PRODUTOS VETERINARIOS LTDA:ME; TURVOVET PRODUTOS VETERINARIOS LTDA:ME; AGRO RIOS - PRODUTOS AGROPECUARIOS LTDA:ME; LE BUREAU - SOLUCOES EM ENGENHARIA LTDA:ME; APLICAPET 39724032 PRODUTOS E SERVICOS VETERINARIOS LTDA:ME; SELARIA FILIMAR LTDA:ME; ARTEFATOS JULIANE LTDA:ME; 63.816.832 MATHEUS KAYTHON DO CARMO:ME; JOSE DANTAS DINIZ FILHO:ME; 66.912.461 CLAUDIO GABRIEL PEREIRA DE MENEZES:ME; AGROBRAGA COMERCIO E SERVICOS LTDA:ME; SELARIA IRMAOS ANDRADE LTDA:ME | AH33: pontual | AJ33: 0 | AK33: 0 | AL33: 0 | AM33: 0 | AN33: 0 | AQ33: 1 | AR33: fora_escopo | AS33: Aquisição de materiais/insumos/alimentos/medicamentos veterinários para efetivo animal do Exército; falso positivo de indexação, sem relação com munck. | AT33: 0 | AU33: 0
A34: 00394452000103_2026_15739 | B34: https://pncp.gov.br/app/editais/00394452000103/2026/15739 | C34: 2026-09-27T02:30:10.168580+00:00 | D34: GO | E34: GO | F34: Jataí | G34: COMANDO DO EXERCITO | H34: Federal | I34: 2026-08-05T04:00:04 | J34: Pregão - Eletrônico | K34: Contratação de serviços de instalação de ar condicionado e manutenção de máquinas e equipamentos. | L34: TRUE | M34: climatizacao | N34: climatizacao | O34: 116783.28 | P34: 58382 | Q34: 116783.28 | R34: 0.50008255 | S34: 0 | T34: 28 | U34: 28 | V34: 28 | W34: 0 | X34: 0 | Y34: 0 | Z34: 0 | AA34: 1 | AB34: 0 | AC34: 0 | AD34: 0 | AE34: 3 | AF34: 45.248.096 BRUNO RODRIGUES SILVEIRA ALVES:ME; PALADINI & PALADINI LTDA:ME; FERNANDO COMEL & CIA LTDA:ME | AH34: pontual | AI34: 12 | AJ34: 0 | AK34: 0 | AL34: 0 | AM34: 1 | AN34: 0 | AQ34: 0 | AS34: heuristica automatica confirmada: servico real de climatizacao, sem sinais de exclusao. | AT34: 0 | AU34: 1
A35: 00394494000136_2026_812 | B35: https://pncp.gov.br/app/editais/00394494000136/2026/812 | C35: 2026-09-27T04:52:46.894571+00:00 | D35: DF | E35: vizinhos | F35: Brasília | G35: MINISTERIO DA JUSTICA E SEGURANCA PUBLICA | H35: Federal | I35: 2026-08-04T04:03:07 | J35: Pregão - Eletrônico | K35: Manutenção predial corretiva e preventiva para o edifício sede da Secretaria Nacional de Políticas Penais (SENAPPEN), situado no SCN Q. 4 - Bl. A, Ed. MultiBrasil, Torre "A" - Asa Norte, Brasília/DF. | L35: FALSE | M35: manutencao_predial | N35: manutencao_predial | O35: 2109078 | P35: 1686207.9 | Q35: 2109078 | R35: 0.2005 | S35: 0 | T35: 1 | U35: 1 | V35: 1 | W35: 0 | X35: 0 | Y35: 0 | Z35: 0 | AA35: 0 | AB35: 0 | AC35: 0 | AD35: 0 | AE35: 1 | AF35: DASK EMPREENDIMENTOS LTDA:ME | AH35: indefinido | AJ35: 0 | AK35: 0 | AL35: 0 | AM35: 0 | AN35: 0 | AQ35: 0 | AT35: 0 | AU35: 1
A36: 00394494010441_2026_523 | B36: https://pncp.gov.br/app/editais/00394494010441/2026/523 | C36: 2026-09-27T04:56:29.025892+00:00 | D36: DF | E36: vizinhos | F36: Brasília | G36: MINISTERIO DA JUSTICA E SEGURANCA PUBLICA | H36: Federal | I36: 2026-07-13T04:00:02 | J36: Pregão - Eletrônico | K36: Registro de preços para eventual e futura aquisição de radar portátil móvel, iluminador e tripé, em grupo único, conforme condições, quantidades e exigências estabelecidas no Edital e seus anexos | L36: TRUE | M36: iluminacao_publica | N36: iluminacao_publica | O36: 55121114 | P36: 54951360 | Q36: 55121114 | R36: 0.0030796547 | S36: 0 | T36: 3 | U36: 3 | V36: 3 | W36: 0 | X36: 0 | Y36: 0 | Z36: 0 | AA36: 0 | AB36: 0 | AC36: 0 | AD36: 0 | AE36: 1 | AF36: LT COMERCIAL LTDA:Demais | AH36: pontual | AJ36: 0 | AK36: 0 | AL36: 0 | AM36: 0 | AN36: 0 | AQ36: 1 | AR36: mencao_passagem | AS36: Aquisição de radar portátil, iluminador e tripé (equipamento de fiscalização); falso positivo de palavra-chave, não é IP. | AT36: 0 | AU36: 0
A37: 00394502000144_2026_7871 | B37: https://pncp.gov.br/app/editais/00394502000144/2026/7871 | C37: 2026-09-27T04:56:23.197638+00:00 | D37: DF | E37: vizinhos | F37: Brasília | G37: COMANDO DA MARINHA | H37: Federal | I37: 2026-07-15T04:00:09 | J37: Pregão - Eletrônico | K37: Contratação de serviços de engenharia para elaboração de projeto executivo, execução da modernização e prestação de manutenção integral de 12 (doze) elevadores elétricos, instalados em edifícios de Próprios Nacionais Residenciais, localizados nos Blocos "C" e "G" da SQS 202, em Brasília / DF. | L37: FALSE | M37: eletrica_predial | N37: eletrica_predial | O37: 3340839.4 | P37: 2895817.9 | Q37: 3340839.4 | R37: 0.13320649 | S37: 0 | T37: 1 | U37: 1 | V37: 1 | W37: 0 | X37: 0 | Y37: 0 | Z37: 0 | AA37: 0 | AB37: 0 | AC37: 0 | AD37: 0 | AE37: 1 | AF37: ONE ELEVADORES DF LTDA.:Demais | AH37: indefinido | AJ37: 0 | AK37: 0 | AL37: 0 | AM37: 0 | AN37: 0 | AQ37: 0 | AR37: fora_de_escopo | AS37: Manutencao de 12 elevadores eletricos e nicho tecnico distinto (regulado por norma propria de elevadores), fora do escopo de eletrica predial/SPDA/subestacao e da capacidade tipica da empresa. | AT37: 0 | AU37: 0
A38: 00394544000185_2026_1654 | B38: https://pncp.gov.br/app/editais/00394544000185/2026/1654 | C38: 2026-09-27T05:20:06.887174+00:00 | D38: MS | E38: vizinhos | F38: Campo Grande | G38: MINISTERIO DA SAUDE | H38: Federal | I38: 2026-08-12T04:00:14 | J38: Pregão - Eletrônico | K38: Aquisição de materiais elétricos para as manutenções realizadas em quadros de comando e edificações das aldeias, pertencentes às áreas de abrangência do Distrito Sanitário Especial Indígena Mato Grosso do Sul - DSEI/MS. | L38: TRUE | M38: eletrica_predial | N38: eletrica_predial | O38: 998667.75 | P38: 201161.35 | Q38: 324019.1 | R38: 0.37916824 | S38: 0 | T38: 67 | U38: 40 | V38: 66 | W38: 0 | X38: 1 | Y38: 0 | Z38: 1 | AA38: 0 | AB38: 1 | AC38: 0 | AD38: 0 | AE38: 10 | AF38: VM COMERCIO E IMPORTACAO LTDA:ME; SOUZA ALVES & CIA LTDA:ME; FERNANDES PROFETA ATACADISTA LTDA:ME; RRW LICITA LTDA:ME; D33D COMERCIO LTDA:ME; CBX COMERCIAL IMPORTADORA LTDA:ME; GR COMERCIO LTDA:ME; MRJ MATERIAIS E SERVICOS ELETRICOS LTDA:ME; UP CENTER COMERCIO DE UTILIDADES LTDA:ME; N DE SOUZA AUTOMACOES:ME | AH38: pontual | AJ38: 0 | AK38: 0 | AL38: 0 | AM38: 0 | AN38: 0 | AQ38: 1 | AR38: fornecimento_puro | AS38: Confirmada exclusao automatica (fornecimento_puro): 67 item(ns), todos classificados como material (sem servico). | AT38: 1 | AU38: 0
A39: 00394684000153_2026_104 | B39: https://pncp.gov.br/app/editais/00394684000153/2026/104 | C39: 2026-09-27T04:56:19.033695+00:00 | D39: DF | E39: vizinhos | F39: Brasília | G39: SECRETARIA DE ESTADO DE ECONOMIA DO DISTRITO FEDERAL | H39: Distrital | I39: 2026-07-17T07:00:49 | J39: Pregão - Eletrônico | K39: Pregão eletrônico, na modalidade Registro de Preços, destinado a aquisição de materiais de consumo, compreendendo materiais diversos utilizados em serviços de serralheria, pintura, hidráulica, acabamentos, pisos, instalações elétricas e alvenaria, destinados à manutenção das atividades desenvolvidas nas Oficinas de Serralheria, Alvenaria e Pintura da Fundação de Amparo ao Trabalhador Preso do Distrito Federal – FUNAP/DF. | L39: TRUE | M39: eletrica_predial | N39: eletrica_predial | O39: 559807.17 | P39: 328939.3 | Q39: 434279.86 | R39: 0.24256377 | S39: 0 | T39: 88 | U39: 40 | V39: 88 | W39: 0 | X39: 0 | Y39: 0 | Z39: 0 | AA39: 0 | AB39: 1 | AC39: 0 | AD39: 0 | AE39: 8 | AF39: MGE ADVENTURY LTDA:ME; SANDU COMERCIO E DISTRIBUICAO DE PRODUTOS LTDA:ME; ATRIUM INDUSTRIA E COMERCIO DE FERRAGENS LTDA:ME; ING - DISTRIBUICAO LTDA:ME; DIPAR FERRAGENS LTDA:ME; DF MAQUINAS E FERRAMENTAS LTDA:ME; HANDOUR COMERCIAL E VAREJO LTDA:ME; MARMORARIA PEDRA BONITA LTDA:ME | AH39: pontual | AJ39: 0 | AK39: 0 | AL39: 0 | AM39: 0 | AN39: 0 | AQ39: 1 | AR39: fornecimento_puro | AS39: Confirmada exclusao automatica (fornecimento_puro): 88 item(ns), todos classificados como material (sem servico). | AT39: 1 | AU39: 0
A40: 00394684000153_2026_113 | B40: https://pncp.gov.br/app/editais/00394684000153/2026/113 | C40: 2026-09-27T04:55:36.033376+00:00 | D40: DF | E40: vizinhos | F40: Brasília | G40: SECRETARIA DE ESTADO DE ECONOMIA DO DISTRITO FEDERAL | H40: Distrital | I40: 2026-08-03T15:33:51 | J40: Pregão - Eletrônico | K40: Registro de Preços a fim de possibilitar a futura aquisição de material elétrico e eletrônico (cabo elétrico, disjuntor, interruptor, tomada, soquete, dentre outros similares), para atender às necessidades dos diversos órgãos e entidades que compõem a estrutura administrativa do Distrito Federal, conforme especificações e condições estabelecidas no termo de referência constante do Anexo I do Edital. | L40: TRUE | M40: eletrica_predial | N40: eletrica_predial | O40: 5477834 | P40: 3517664.8 | Q40: 3654773.8 | R40: 0.03751503 | S40: 0 | T40: 96 | U40: 40 | V40: 72 | W40: 0 | X40: 24 | Y40: 0 | Z40: 1 | AA40: 0 | AB40: 1 | AC40: 0 | AD40: 0 | AE40: 1 | AF40: SUNLED INDUSTRIA E COMERCIO DE MATERIAIS ELETRICOS LTDA:ME | AH40: pontual | AJ40: 0 | AK40: 0 | AL40: 0 | AM40: 0 | AN40: 0 | AQ40: 1 | AR40: fornecimento_puro | AS40: Confirmada exclusao automatica (fornecimento_puro): 96 item(ns), todos classificados como material (sem servico). | AT40: 0 | AU40: 0
...

Sheet indicadores_por_area
A1: area | B1: grupo_uf | C1: volume_ano_indice (copiado de indicadores.json) | D1: n_casos_detalhados (formula) | E1: valor_total_estimado (formula) | F1: ticket_mediano (formula) | G1: mediana_participantes (formula) | H1: n_amostra_participantes (formula) | I1: desconto_mediana (formula) | J1: desconto_q1 (formula) | K1: desconto_q3 (formula) | L1: n_amostra_desconto (formula) | M1: pct_deserta_ou_fracassada (formula) | N1: pct_exclusiva_meepp (formula) | O1: pct_exclusiva_parcial_meepp (formula) | P1: pct_cota_meepp (formula) | Q1: pct_continuado (formula)
A2: climatizacao | B2: GO | C2: 46 | D2: =COUNTIFS(dados_brutos!$M$2:$M$536,"*"&"climatizacao"&"*",dados_brutos!$E$2:$E$536,"GO",dados_brutos!$AU$2:$AU$536,1) | E2: =IF(SUMPRODUCT((ISNUMBER(SEARCH("climatizacao",dados_brutos!$M$2:$M$536))*(dados_brutos!$E$2:$E$536="GO")*(dados_brutos!$AU$2:$AU$536=1))*ISNUMBER(dados_brutos!$O$2:$O$536))=0,"",SUMIFS(dados_brutos!$O$2:$O$536,dados_brutos!$M$2:$M$536,"*"&"climatizacao"&"*",dados_brutos!$E$2:$E$536,"GO",dados_brutos!$AU$2:$AU$536,1)) | F2: =IF(SUMPRODUCT((ISNUMBER(SEARCH("climatizacao",dados_brutos!$M$2:$M$536))*(dados_brutos!$E$2:$E$536="GO")*(dados_brutos!$AU$2:$AU$536=1))*ISNUMBER(dados_brutos!$O$2:$O$536))=0,"",_xlfn.AGGREGATE(12,6,dados_brutos!$O$2:$O$536/((ISNUMBER(SEARCH("climatizacao",dados_brutos!$M$2:$M$536))*(dados_brutos!$E$2:$E$536="GO")*(dados_brutos!$AU$2:$AU$536=1))*ISNUMBER(dados_brutos!$O$2:$O$536)))) | G2: =IF(SUMPRODUCT((ISNUMBER(SEARCH("climatizacao",dados_brutos!$M$2:$M$536))*(dados_brutos!$E$2:$E$536="GO")*(dados_brutos!$AU$2:$AU$536=1))*ISNUMBER(dados_brutos!$AG$2:$AG$536))=0,"",_xlfn.AGGREGATE(12,6,dados_brutos!$AG$2:$AG$536/((ISNUMBER(SEARCH("climatizacao",dados_brutos!$M$2:$M$536))*(dados_brutos!$E$2:$E$536="GO")*(dados_brutos!$AU$2:$AU$536=1))*ISNUMBER(dados_brutos!$AG$2:$AG$536)))) | H2: =SUMPRODUCT((ISNUMBER(SEARCH("climatizacao",dados_brutos!$M$2:$M$536))*(dados_brutos!$E$2:$E$536="GO")*(dados_brutos!$AU$2:$AU$536=1))*ISNUMBER(dados_brutos!$AG$2:$AG$536)) | I2: =IF(SUMPRODUCT((ISNUMBER(SEARCH("climatizacao",dados_brutos!$M$2:$M$536))*(dados_brutos!$E$2:$E$536="GO")*(dados_brutos!$AU$2:$AU$536=1))*ISNUMBER(dados_brutos!$R$2:$R$536))=0,"",_xlfn.AGGREGATE(12,6,dados_brutos!$R$2:$R$536/((ISNUMBER(SEARCH("climatizacao",dados_brutos!$M$2:$M$536))*(dados_brutos!$E$2:$E$536="GO")*(dados_brutos!$AU$2:$AU$536=1))*ISNUMBER(dados_brutos!$R$2:$R$536)))) | J2: =IF(SUMPRODUCT((ISNUMBER(SEARCH("climatizacao",dados_brutos!$M$2:$M$536))*(dados_brutos!$E$2:$E$536="GO")*(dados_brutos!$AU$2:$AU$536=1))*ISNUMBER(dados_brutos!$R$2:$R$536))=0,"",_xlfn.AGGREGATE(17,6,dados_brutos!$R$2:$R$536/((ISNUMBER(SEARCH("climatizacao",dados_brutos!$M$2:$M$536))*(dados_brutos!$E$2:$E$536="GO")*(dados_brutos!$AU$2:$AU$536=1))*ISNUMBER(dados_brutos!$R$2:$R$536)),1)) | K2: =IF(SUMPRODUCT((ISNUMBER(SEARCH("climatizacao",dados_brutos!$M$2:$M$536))*(dados_brutos!$E$2:$E$536="GO")*(dados_brutos!$AU$2:$AU$536=1))*ISNUMBER(dados_brutos!$R$2:$R$536))=0,"",_xlfn.AGGREGATE(17,6,dados_brutos!$R$2:$R$536/((ISNUMBER(SEARCH("climatizacao",dados_brutos!$M$2:$M$536))*(dados_brutos!$E$2:$E$536="GO")*(dados_brutos!$AU$2:$AU$536=1))*ISNUMBER(dados_brutos!$R$2:$R$536)),3)) | L2: =SUMPRODUCT((ISNUMBER(SEARCH("climatizacao",dados_brutos!$M$2:$M$536))*(dados_brutos!$E$2:$E$536="GO")*(dados_brutos!$AU$2:$AU$536=1))*ISNUMBER(dados_brutos!$R$2:$R$536)) | M2: =IF(COUNTIFS(dados_brutos!$M$2:$M$536,"*"&"climatizacao"&"*",dados_brutos!$E$2:$E$536,"GO",dados_brutos!$AU$2:$AU$536,1)=0,"",COUNTIFS(dados_brutos!$M$2:$M$536,"*"&"climatizacao"&"*",dados_brutos!$E$2:$E$536,"GO",dados_brutos!$AU$2:$AU$536,1,dados_brutos!$Z$2:$Z$536,1)/COUNTIFS(dados_brutos!$M$2:$M$536,"*"&"climatizacao"&"*",dados_brutos!$E$2:$E$536,"GO",dados_brutos!$AU$2:$AU$536,1)) | N2: =IF(COUNTIFS(dados_brutos!$M$2:$M$536,"*"&"climatizacao"&"*",dados_brutos!$E$2:$E$536,"GO",dados_brutos!$AU$2:$AU$536,1)=0,"",COUNTIFS(dados_brutos!$M$2:$M$536,"*"&"climatizacao"&"*",dados_brutos!$E$2:$E$536,"GO",dados_brutos!$AU$2:$AU$536,1,dados_brutos!$AA$2:$AA$536,1)/COUNTIFS(dados_brutos!$M$2:$M$536,"*"&"climatizacao"&"*",dados_brutos!$E$2:$E$536,"GO",dados_brutos!$AU$2:$AU$536,1)) | O2: =IF(COUNTIFS(dados_brutos!$M$2:$M$536,"*"&"climatizacao"&"*",dados_brutos!$E$2:$E$536,"GO",dados_brutos!$AU$2:$AU$536,1)=0,"",COUNTIFS(dados_brutos!$M$2:$M$536,"*"&"climatizacao"&"*",dados_brutos!$E$2:$E$536,"GO",dados_brutos!$AU$2:$AU$536,1,dados_brutos!$AB$2:$AB$536,1)/COUNTIFS(dados_brutos!$M$2:$M$536,"*"&"climatizacao"&"*",dados_brutos!$E$2:$E$536,"GO",dados_brutos!$AU$2:$AU$536,1)) | P2: =IF(COUNTIFS(dados_brutos!$M$2:$M$536,"*"&"climatizacao"&"*",dados_brutos!$E$2:$E$536,"GO",dados_brutos!$AU$2:$AU$536,1)=0,"",COUNTIFS(dados_brutos!$M$2:$M$536,"*"&"climatizacao"&"*",dados_brutos!$E$2:$E$536,"GO",dados_brutos!$AU$2:$AU$536,1,dados_brutos!$AC$2:$AC$536,1)/COUNTIFS(dados_brutos!$M$2:$M$536,"*"&"climatizacao"&"*",dados_brutos!$E$2:$E$536,"GO",dados_brutos!$AU$2:$AU$536,1)) | Q2: =IF(COUNTIFS(dados_brutos!$M$2:$M$536,"*"&"climatizacao"&"*",dados_brutos!$E$2:$E$536,"GO",dados_brutos!$AU$2:$AU$536,1)=0,"",COUNTIFS(dados_brutos!$M$2:$M$536,"*"&"climatizacao"&"*",dados_brutos!$E$2:$E$536,"GO",dados_brutos!$AU$2:$AU$536,1,dados_brutos!$AH$2:$AH$536,"continuado")/COUNTIFS(dados_brutos!$M$2:$M$536,"*"&"climatizacao"&"*",dados_brutos!$E$2:$E$536,"GO",dados_brutos!$AU$2:$AU$536,1))
